***2025-02-22 16:03:00.833621+00:00***: os.path.join(BASE_DIR, f'{id}')='qPCR_ozaki/82ef653d-95dd-406f-9e6c-bb355a43e58b/iteration_8'***2025-02-22 16:03:00.833891+00:00***: *********************** 82ef653d-95dd-406f-9e6c-bb355a43e58b/iteration_8 *****************************2025-02-22 16:03:00.834129+00:00***: *********************************************************2025-02-22 16:03:09.171636+00:00***: obj-chan preprocess result:

{
  "labware": [
    {
      "name": "sample DNAs",
      "quantity": 300,
      "unit": "µL",
      "init_content": "",
      "labware": {
        "id": 1,
        "name": "Unknown"
      }
    },
    {
      "name": "water",
      "quantity": 300,
      "unit": "µL",
      "init_content": "",
      "labware": {
        "id": 1,
        "name": "Unknown"
      }
    },
    {
      "name": "10 µM primer_F",
      "quantity": 10,
      "unit": "µL",
      "init_content": "",
      "labware": {
        "id": 1,
        "name": "Unknown"
      }
    },
    {
      "name": "10 µM primer_R",
      "quantity": 10,
      "unit": "µL",
      "init_content": "",
      "labware": {
        "id": 1,
        "name": "Unknown"
      }
    },
    {
      "name": "PCR MIX",
      "quantity": 2000,
      "unit": "µL",
      "init_content": "",
      "labware": {
        "id": 1,
        "name": "Unknown"
      }
    },
    {
      "name": "96 well PCR plate",
      "quantity": 1,
      "unit": "plate",
      "init_content": "",
      "labware": {
        "id": 1,
        "name": "Unknown"
      }
    },
    {
      "name": "empty tube",
      "quantity": 0,
      "unit": "",
      "init_content": "",
      "labware": {
        "id": 1,
        "name": "Unknown"
      }
    },
    {
      "name": "template",
      "quantity": 86,
      "unit": "µL",
      "init_content": "",
      "labware": {
        "id": 1,
        "name": "Unknown"
      }
    },
    {
      "name": "water",
      "quantity": 4,
      "unit": "µL",
      "init_content": "",
      "labware": {
        "id": 1,
        "name": "Unknown"
      }
    },
    {
      "name": "reaction plate",
      "quantity": 5,
      "unit": "µL",
      "init_content": "",
      "labware": {
        "id": 1,
        "name": "Unknown"
      }
    }
  ]
}

Note: Since the labware names are not specified in the given text, the labware field has been left as "Unknown".***2025-02-22 16:03:09.173569+00:00***: obj-chan postprocess result:

{
  "labware": [
    {
      "name": "sample DNAs",
      "quantity": 300,
      "unit": "µL",
      "init_content": "",
      "labware": {
        "id": 1,
        "name": "Unknown"
      }
    },
    {
      "name": "water",
      "quantity": 300,
      "unit": "µL",
      "init_content": "",
      "labware": {
        "id": 1,
        "name": "Unknown"
      }
    },
    {
      "name": "10 µM primer_F",
      "quantity": 10,
      "unit": "µL",
      "init_content": "",
      "labware": {
        "id": 1,
        "name": "Unknown"
      }
    },
    {
      "name": "10 µM primer_R",
      "quantity": 10,
      "unit": "µL",
      "init_content": "",
      "labware": {
        "id": 1,
        "name": "Unknown"
      }
    },
    {
      "name": "PCR MIX",
      "quantity": 2000,
      "unit": "µL",
      "init_content": "",
      "labware": {
        "id": 1,
        "name": "Unknown"
      }
    },
    {
      "name": "96 well PCR plate",
      "quantity": 1,
      "unit": "plate",
      "init_content": "",
      "labware": {
        "id": 1,
        "name": "Unknown"
      }
    },
    {
      "name": "empty tube",
      "quantity": 0,
      "unit": "",
      "init_content": "",
      "labware": {
        "id": 1,
        "name": "Unknown"
      }
    },
    {
      "name": "template",
      "quantity": 86,
      "unit": "µL",
      "init_content": "",
      "labware": {
        "id": 1,
        "name": "Unknown"
      }
    },
    {
      "name": "water",
      "quantity": 4,
      "unit": "µL",
      "init_content": "",
      "labware": {
        "id": 1,
        "name": "Unknown"
      }
    },
    {
      "name": "reaction plate",
      "quantity": 5,
      "unit": "µL",
      "init_content": "",
      "labware": {
        "id": 1,
        "name": "Unknown"
      }
    }
  ]
}

Note: Since the labware names are not specified in the given text, the labware field has been left as "Unknown".***2025-02-22 16:03:09.174446+00:00***: Attempt 1 failed with error: Extra data: line 106 column 1 (char 1819)***2025-02-22 16:03:09.175736+00:00***: Traceback: Traceback (most recent call last):
  File "/Users/yuyaarai/Documents/Humanics/Project/FormationFormatter/src/formationformatter/functions.py", line 45, in get_object_list
    object_list, obj_chan_errors = obj_chan(
                                   ^^^^^^^^^
  File "/Users/yuyaarai/Documents/Humanics/Project/FormationFormatter/src/formationformatter/obj_chan/__init__.py", line 265, in run
    res, errors = get_object_list(process_flow, constraints, messages, log_file_path=log_file_path)
                  ^^^^^^^^^^^^^^^^^^^^^^^^^^^^^^^^^^^^^^^^^^^^^^^^^^^^^^^^^^^^^^^^^^^^^^^^^^^^^^^^^
  File "/Users/yuyaarai/Documents/Humanics/Project/FormationFormatter/src/formationformatter/obj_chan/__init__.py", line 252, in get_object_list
    results = _extract_results_from_gpt_response(answer, log_file_path)
              ^^^^^^^^^^^^^^^^^^^^^^^^^^^^^^^^^^^^^^^^^^^^^^^^^^^^^^^^^
  File "/Users/yuyaarai/Documents/Humanics/Project/FormationFormatter/src/formationformatter/obj_chan/__init__.py", line 135, in _extract_results_from_gpt_response
    results = text_to_dict(result.replace('extracted_results:', '').replace('extracted_results_end:', '').strip())
              ^^^^^^^^^^^^^^^^^^^^^^^^^^^^^^^^^^^^^^^^^^^^^^^^^^^^^^^^^^^^^^^^^^^^^^^^^^^^^^^^^^^^^^^^^^^^^^^^^^^^
  File "/Users/yuyaarai/Documents/Humanics/Project/FormationFormatter/src/formationformatter/obj_chan/__init__.py", line 134, in <lambda>
    text_to_dict = lambda x: json.loads(x.replace('\'', '\"'))
                             ^^^^^^^^^^^^^^^^^^^^^^^^^^^^^^^^^
  File "/opt/homebrew/Cellar/python@3.12/3.12.8/Frameworks/Python.framework/Versions/3.12/lib/python3.12/json/__init__.py", line 346, in loads
    return _default_decoder.decode(s)
           ^^^^^^^^^^^^^^^^^^^^^^^^^^
  File "/opt/homebrew/Cellar/python@3.12/3.12.8/Frameworks/Python.framework/Versions/3.12/lib/python3.12/json/decoder.py", line 341, in decode
    raise JSONDecodeError("Extra data", s, end)
json.decoder.JSONDecodeError: Extra data: line 106 column 1 (char 1819)
***2025-02-22 16:03:09.176332+00:00***: Retrying... (Attempt 1/10)***2025-02-22 16:03:13.191744+00:00***: obj-chan preprocess result:

{
  "labware": [
    {
      "name": "1.5 ml tube",
      "quantity": 1,
      "unit": "sample",
      "init_content": "",
      "labware": {
        "id": 1,
        "name": "1.5 ml tube"
      }
    },
    {
      "name": "96 well PCR plate",
      "quantity": 1,
      "unit": "plate",
      "init_content": "",
      "labware": {
        "id": 2,
        "name": "96 well PCR plate"
      }
    },
    {
      "name": "15 ml tube",
      "quantity": 1,
      "unit": "medium",
      "init_content": "",
      "labware": {
        "id": 3,
        "name": "15 ml tube"
      }
    }
  ]
}

Note: Since the labware mentioned in the given text is not already specified in the available labware list, the labware field has been left as "Unknown".***2025-02-22 16:03:13.194102+00:00***: obj-chan postprocess result:

{
  "labware": [
    {
      "name": "1.5 ml tube",
      "quantity": 1,
      "unit": "sample",
      "init_content": "",
      "labware": {
        "id": 1,
        "name": "1.5 ml tube"
      }
    },
    {
      "name": "96 well PCR plate",
      "quantity": 1,
      "unit": "plate",
      "init_content": "",
      "labware": {
        "id": 2,
        "name": "96 well PCR plate"
      }
    },
    {
      "name": "15 ml tube",
      "quantity": 1,
      "unit": "medium",
      "init_content": "",
      "labware": {
        "id": 3,
        "name": "15 ml tube"
      }
    }
  ]
}

Note: Since the labware mentioned in the given text is not already specified in the available labware list, the labware field has been left as "Unknown".***2025-02-22 16:03:13.197242+00:00***: Attempt 2 failed with error: Extra data: line 36 column 1 (char 593)***2025-02-22 16:03:13.199781+00:00***: Traceback: Traceback (most recent call last):
  File "/Users/yuyaarai/Documents/Humanics/Project/FormationFormatter/src/formationformatter/functions.py", line 45, in get_object_list
    object_list, obj_chan_errors = obj_chan(
                                   ^^^^^^^^^
  File "/Users/yuyaarai/Documents/Humanics/Project/FormationFormatter/src/formationformatter/obj_chan/__init__.py", line 265, in run
    res, errors = get_object_list(process_flow, constraints, messages, log_file_path=log_file_path)
                  ^^^^^^^^^^^^^^^^^^^^^^^^^^^^^^^^^^^^^^^^^^^^^^^^^^^^^^^^^^^^^^^^^^^^^^^^^^^^^^^^^
  File "/Users/yuyaarai/Documents/Humanics/Project/FormationFormatter/src/formationformatter/obj_chan/__init__.py", line 252, in get_object_list
    results = _extract_results_from_gpt_response(answer, log_file_path)
              ^^^^^^^^^^^^^^^^^^^^^^^^^^^^^^^^^^^^^^^^^^^^^^^^^^^^^^^^^
  File "/Users/yuyaarai/Documents/Humanics/Project/FormationFormatter/src/formationformatter/obj_chan/__init__.py", line 135, in _extract_results_from_gpt_response
    results = text_to_dict(result.replace('extracted_results:', '').replace('extracted_results_end:', '').strip())
              ^^^^^^^^^^^^^^^^^^^^^^^^^^^^^^^^^^^^^^^^^^^^^^^^^^^^^^^^^^^^^^^^^^^^^^^^^^^^^^^^^^^^^^^^^^^^^^^^^^^^
  File "/Users/yuyaarai/Documents/Humanics/Project/FormationFormatter/src/formationformatter/obj_chan/__init__.py", line 134, in <lambda>
    text_to_dict = lambda x: json.loads(x.replace('\'', '\"'))
                             ^^^^^^^^^^^^^^^^^^^^^^^^^^^^^^^^^
  File "/opt/homebrew/Cellar/python@3.12/3.12.8/Frameworks/Python.framework/Versions/3.12/lib/python3.12/json/__init__.py", line 346, in loads
    return _default_decoder.decode(s)
           ^^^^^^^^^^^^^^^^^^^^^^^^^^
  File "/opt/homebrew/Cellar/python@3.12/3.12.8/Frameworks/Python.framework/Versions/3.12/lib/python3.12/json/decoder.py", line 341, in decode
    raise JSONDecodeError("Extra data", s, end)
json.decoder.JSONDecodeError: Extra data: line 36 column 1 (char 593)
***2025-02-22 16:03:13.201930+00:00***: Retrying... (Attempt 2/10)***2025-02-22 16:03:16.080802+00:00***: obj-chan preprocess result:

{
  "labware": [
    {
      "name": "1.5 ml tube",
      "quantity": 1,
      "unit": "tube",
      "init_content": "",
      "labware": {
        "id": 1,
        "name": "Unknown"
      }
    },
    {
      "name": "96 well PCR plate",
      "quantity": 1,
      "unit": "plate",
      "init_content": "",
      "labware": {
        "id": 2,
        "name": "Unknown"
      }
    },
    {
      "name": "15 ml tube",
      "quantity": 1,
      "unit": "tube",
      "init_content": "",
      "labware": {
        "id": 3,
        "name": "Unknown"
      }
    }
  ]
}

Note: Since the labware mentioned in the given text is not already specified in the available labware list, the labware field has been left as "Unknown".***2025-02-22 16:03:16.083738+00:00***: obj-chan postprocess result:

{
  "labware": [
    {
      "name": "1.5 ml tube",
      "quantity": 1,
      "unit": "tube",
      "init_content": "",
      "labware": {
        "id": 1,
        "name": "Unknown"
      }
    },
    {
      "name": "96 well PCR plate",
      "quantity": 1,
      "unit": "plate",
      "init_content": "",
      "labware": {
        "id": 2,
        "name": "Unknown"
      }
    },
    {
      "name": "15 ml tube",
      "quantity": 1,
      "unit": "tube",
      "init_content": "",
      "labware": {
        "id": 3,
        "name": "Unknown"
      }
    }
  ]
}

Note: Since the labware mentioned in the given text is not already specified in the available labware list, the labware field has been left as "Unknown".***2025-02-22 16:03:16.085356+00:00***: Attempt 3 failed with error: Extra data: line 36 column 1 (char 572)***2025-02-22 16:03:16.087293+00:00***: Traceback: Traceback (most recent call last):
  File "/Users/yuyaarai/Documents/Humanics/Project/FormationFormatter/src/formationformatter/functions.py", line 45, in get_object_list
    object_list, obj_chan_errors = obj_chan(
                                   ^^^^^^^^^
  File "/Users/yuyaarai/Documents/Humanics/Project/FormationFormatter/src/formationformatter/obj_chan/__init__.py", line 265, in run
    res, errors = get_object_list(process_flow, constraints, messages, log_file_path=log_file_path)
                  ^^^^^^^^^^^^^^^^^^^^^^^^^^^^^^^^^^^^^^^^^^^^^^^^^^^^^^^^^^^^^^^^^^^^^^^^^^^^^^^^^
  File "/Users/yuyaarai/Documents/Humanics/Project/FormationFormatter/src/formationformatter/obj_chan/__init__.py", line 252, in get_object_list
    results = _extract_results_from_gpt_response(answer, log_file_path)
              ^^^^^^^^^^^^^^^^^^^^^^^^^^^^^^^^^^^^^^^^^^^^^^^^^^^^^^^^^
  File "/Users/yuyaarai/Documents/Humanics/Project/FormationFormatter/src/formationformatter/obj_chan/__init__.py", line 135, in _extract_results_from_gpt_response
    results = text_to_dict(result.replace('extracted_results:', '').replace('extracted_results_end:', '').strip())
              ^^^^^^^^^^^^^^^^^^^^^^^^^^^^^^^^^^^^^^^^^^^^^^^^^^^^^^^^^^^^^^^^^^^^^^^^^^^^^^^^^^^^^^^^^^^^^^^^^^^^
  File "/Users/yuyaarai/Documents/Humanics/Project/FormationFormatter/src/formationformatter/obj_chan/__init__.py", line 134, in <lambda>
    text_to_dict = lambda x: json.loads(x.replace('\'', '\"'))
                             ^^^^^^^^^^^^^^^^^^^^^^^^^^^^^^^^^
  File "/opt/homebrew/Cellar/python@3.12/3.12.8/Frameworks/Python.framework/Versions/3.12/lib/python3.12/json/__init__.py", line 346, in loads
    return _default_decoder.decode(s)
           ^^^^^^^^^^^^^^^^^^^^^^^^^^
  File "/opt/homebrew/Cellar/python@3.12/3.12.8/Frameworks/Python.framework/Versions/3.12/lib/python3.12/json/decoder.py", line 341, in decode
    raise JSONDecodeError("Extra data", s, end)
json.decoder.JSONDecodeError: Extra data: line 36 column 1 (char 572)
***2025-02-22 16:03:16.088355+00:00***: Retrying... (Attempt 3/10)***2025-02-22 16:03:19.415636+00:00***: obj-chan preprocess result:

{
  "labware": [
    {
      "name": "1.5 ml tube",
      "quantity": 1,
      "unit": "tube",
      "init_content": "",
      "labware": {
        "id": 1,
        "name": "1.5 ml tube"
      }
    },
    {
      "name": "96 well PCR plate",
      "quantity": 1,
      "unit": "plate",
      "init_content": "",
      "labware": {
        "id": 2,
        "name": "96 well PCR plate"
      }
    },
    {
      "name": "15 ml tube",
      "quantity": 1,
      "unit": "tube",
      "init_content": "",
      "labware": {
        "id": 3,
        "name": "15 ml tube"
      }
    }
  ]
}

Note: Since the labware mentioned in the given text is not already specified in the available labware list, the labware field has been left as "Unknown".***2025-02-22 16:03:19.416823+00:00***: obj-chan postprocess result:

{
  "labware": [
    {
      "name": "1.5 ml tube",
      "quantity": 1,
      "unit": "tube",
      "init_content": "",
      "labware": {
        "id": 1,
        "name": "1.5 ml tube"
      }
    },
    {
      "name": "96 well PCR plate",
      "quantity": 1,
      "unit": "plate",
      "init_content": "",
      "labware": {
        "id": 2,
        "name": "96 well PCR plate"
      }
    },
    {
      "name": "15 ml tube",
      "quantity": 1,
      "unit": "tube",
      "init_content": "",
      "labware": {
        "id": 3,
        "name": "15 ml tube"
      }
    }
  ]
}

Note: Since the labware mentioned in the given text is not already specified in the available labware list, the labware field has been left as "Unknown".***2025-02-22 16:03:19.417521+00:00***: Attempt 4 failed with error: Extra data: line 36 column 1 (char 589)***2025-02-22 16:03:19.420491+00:00***: Traceback: Traceback (most recent call last):
  File "/Users/yuyaarai/Documents/Humanics/Project/FormationFormatter/src/formationformatter/functions.py", line 45, in get_object_list
    object_list, obj_chan_errors = obj_chan(
                                   ^^^^^^^^^
  File "/Users/yuyaarai/Documents/Humanics/Project/FormationFormatter/src/formationformatter/obj_chan/__init__.py", line 265, in run
    res, errors = get_object_list(process_flow, constraints, messages, log_file_path=log_file_path)
                  ^^^^^^^^^^^^^^^^^^^^^^^^^^^^^^^^^^^^^^^^^^^^^^^^^^^^^^^^^^^^^^^^^^^^^^^^^^^^^^^^^
  File "/Users/yuyaarai/Documents/Humanics/Project/FormationFormatter/src/formationformatter/obj_chan/__init__.py", line 252, in get_object_list
    results = _extract_results_from_gpt_response(answer, log_file_path)
              ^^^^^^^^^^^^^^^^^^^^^^^^^^^^^^^^^^^^^^^^^^^^^^^^^^^^^^^^^
  File "/Users/yuyaarai/Documents/Humanics/Project/FormationFormatter/src/formationformatter/obj_chan/__init__.py", line 135, in _extract_results_from_gpt_response
    results = text_to_dict(result.replace('extracted_results:', '').replace('extracted_results_end:', '').strip())
              ^^^^^^^^^^^^^^^^^^^^^^^^^^^^^^^^^^^^^^^^^^^^^^^^^^^^^^^^^^^^^^^^^^^^^^^^^^^^^^^^^^^^^^^^^^^^^^^^^^^^
  File "/Users/yuyaarai/Documents/Humanics/Project/FormationFormatter/src/formationformatter/obj_chan/__init__.py", line 134, in <lambda>
    text_to_dict = lambda x: json.loads(x.replace('\'', '\"'))
                             ^^^^^^^^^^^^^^^^^^^^^^^^^^^^^^^^^
  File "/opt/homebrew/Cellar/python@3.12/3.12.8/Frameworks/Python.framework/Versions/3.12/lib/python3.12/json/__init__.py", line 346, in loads
    return _default_decoder.decode(s)
           ^^^^^^^^^^^^^^^^^^^^^^^^^^
  File "/opt/homebrew/Cellar/python@3.12/3.12.8/Frameworks/Python.framework/Versions/3.12/lib/python3.12/json/decoder.py", line 341, in decode
    raise JSONDecodeError("Extra data", s, end)
json.decoder.JSONDecodeError: Extra data: line 36 column 1 (char 589)
***2025-02-22 16:03:19.422326+00:00***: Retrying... (Attempt 4/10)***2025-02-22 16:03:22.900643+00:00***: obj-chan preprocess result:

{
  "labware": [
    {
      "name": "1.5 ml tube",
      "quantity": 1,
      "unit": "tube",
      "init_content": "",
      "labware": {
        "id": 1,
        "name": "Unknown"
      }
    },
    {
      "name": "96 well PCR plate",
      "quantity": 1,
      "unit": "plate",
      "init_content": "",
      "labware": {
        "id": 2,
        "name": "Unknown"
      }
    },
    {
      "name": "15 ml tube",
      "quantity": 1,
      "unit": "tube",
      "init_content": "",
      "labware": {
        "id": 3,
        "name": "Unknown"
      }
    }
  ]
}

Note: Since the labware mentioned in the given text is not already specified in the available labware list, the labware field has been left as "Unknown".***2025-02-22 16:03:22.902681+00:00***: obj-chan postprocess result:

{
  "labware": [
    {
      "name": "1.5 ml tube",
      "quantity": 1,
      "unit": "tube",
      "init_content": "",
      "labware": {
        "id": 1,
        "name": "Unknown"
      }
    },
    {
      "name": "96 well PCR plate",
      "quantity": 1,
      "unit": "plate",
      "init_content": "",
      "labware": {
        "id": 2,
        "name": "Unknown"
      }
    },
    {
      "name": "15 ml tube",
      "quantity": 1,
      "unit": "tube",
      "init_content": "",
      "labware": {
        "id": 3,
        "name": "Unknown"
      }
    }
  ]
}

Note: Since the labware mentioned in the given text is not already specified in the available labware list, the labware field has been left as "Unknown".***2025-02-22 16:03:22.903676+00:00***: Attempt 5 failed with error: Extra data: line 36 column 1 (char 572)***2025-02-22 16:03:22.904798+00:00***: Traceback: Traceback (most recent call last):
  File "/Users/yuyaarai/Documents/Humanics/Project/FormationFormatter/src/formationformatter/functions.py", line 45, in get_object_list
    object_list, obj_chan_errors = obj_chan(
                                   ^^^^^^^^^
  File "/Users/yuyaarai/Documents/Humanics/Project/FormationFormatter/src/formationformatter/obj_chan/__init__.py", line 265, in run
    res, errors = get_object_list(process_flow, constraints, messages, log_file_path=log_file_path)
                  ^^^^^^^^^^^^^^^^^^^^^^^^^^^^^^^^^^^^^^^^^^^^^^^^^^^^^^^^^^^^^^^^^^^^^^^^^^^^^^^^^
  File "/Users/yuyaarai/Documents/Humanics/Project/FormationFormatter/src/formationformatter/obj_chan/__init__.py", line 252, in get_object_list
    results = _extract_results_from_gpt_response(answer, log_file_path)
              ^^^^^^^^^^^^^^^^^^^^^^^^^^^^^^^^^^^^^^^^^^^^^^^^^^^^^^^^^
  File "/Users/yuyaarai/Documents/Humanics/Project/FormationFormatter/src/formationformatter/obj_chan/__init__.py", line 135, in _extract_results_from_gpt_response
    results = text_to_dict(result.replace('extracted_results:', '').replace('extracted_results_end:', '').strip())
              ^^^^^^^^^^^^^^^^^^^^^^^^^^^^^^^^^^^^^^^^^^^^^^^^^^^^^^^^^^^^^^^^^^^^^^^^^^^^^^^^^^^^^^^^^^^^^^^^^^^^
  File "/Users/yuyaarai/Documents/Humanics/Project/FormationFormatter/src/formationformatter/obj_chan/__init__.py", line 134, in <lambda>
    text_to_dict = lambda x: json.loads(x.replace('\'', '\"'))
                             ^^^^^^^^^^^^^^^^^^^^^^^^^^^^^^^^^
  File "/opt/homebrew/Cellar/python@3.12/3.12.8/Frameworks/Python.framework/Versions/3.12/lib/python3.12/json/__init__.py", line 346, in loads
    return _default_decoder.decode(s)
           ^^^^^^^^^^^^^^^^^^^^^^^^^^
  File "/opt/homebrew/Cellar/python@3.12/3.12.8/Frameworks/Python.framework/Versions/3.12/lib/python3.12/json/decoder.py", line 341, in decode
    raise JSONDecodeError("Extra data", s, end)
json.decoder.JSONDecodeError: Extra data: line 36 column 1 (char 572)
***2025-02-22 16:03:22.905434+00:00***: Retrying... (Attempt 5/10)***2025-02-22 16:03:26.682966+00:00***: obj-chan preprocess result:

{
  "labware": [
    {
      "name": "1.5 ml tube",
      "quantity": 1,
      "unit": "tube",
      "init_content": "",
      "labware": {
        "id": 1,
        "name": "Unknown"
      }
    },
    {
      "name": "96 well PCR plate",
      "quantity": 1,
      "unit": "plate",
      "init_content": "",
      "labware": {
        "id": 2,
        "name": "Unknown"
      }
    },
    {
      "name": "15 ml tube",
      "quantity": 1,
      "unit": "tube",
      "init_content": "",
      "labware": {
        "id": 3,
        "name": "Unknown"
      }
    }
  ]
}

Note: Since the labware mentioned in the given text is not already specified in the available labware list, the labware field has been left as "Unknown".***2025-02-22 16:03:26.684268+00:00***: obj-chan postprocess result:

{
  "labware": [
    {
      "name": "1.5 ml tube",
      "quantity": 1,
      "unit": "tube",
      "init_content": "",
      "labware": {
        "id": 1,
        "name": "Unknown"
      }
    },
    {
      "name": "96 well PCR plate",
      "quantity": 1,
      "unit": "plate",
      "init_content": "",
      "labware": {
        "id": 2,
        "name": "Unknown"
      }
    },
    {
      "name": "15 ml tube",
      "quantity": 1,
      "unit": "tube",
      "init_content": "",
      "labware": {
        "id": 3,
        "name": "Unknown"
      }
    }
  ]
}

Note: Since the labware mentioned in the given text is not already specified in the available labware list, the labware field has been left as "Unknown".***2025-02-22 16:03:26.684771+00:00***: Attempt 6 failed with error: Extra data: line 36 column 1 (char 572)***2025-02-22 16:03:26.686120+00:00***: Traceback: Traceback (most recent call last):
  File "/Users/yuyaarai/Documents/Humanics/Project/FormationFormatter/src/formationformatter/functions.py", line 45, in get_object_list
    object_list, obj_chan_errors = obj_chan(
                                   ^^^^^^^^^
  File "/Users/yuyaarai/Documents/Humanics/Project/FormationFormatter/src/formationformatter/obj_chan/__init__.py", line 265, in run
    res, errors = get_object_list(process_flow, constraints, messages, log_file_path=log_file_path)
                  ^^^^^^^^^^^^^^^^^^^^^^^^^^^^^^^^^^^^^^^^^^^^^^^^^^^^^^^^^^^^^^^^^^^^^^^^^^^^^^^^^
  File "/Users/yuyaarai/Documents/Humanics/Project/FormationFormatter/src/formationformatter/obj_chan/__init__.py", line 252, in get_object_list
    results = _extract_results_from_gpt_response(answer, log_file_path)
              ^^^^^^^^^^^^^^^^^^^^^^^^^^^^^^^^^^^^^^^^^^^^^^^^^^^^^^^^^
  File "/Users/yuyaarai/Documents/Humanics/Project/FormationFormatter/src/formationformatter/obj_chan/__init__.py", line 135, in _extract_results_from_gpt_response
    results = text_to_dict(result.replace('extracted_results:', '').replace('extracted_results_end:', '').strip())
              ^^^^^^^^^^^^^^^^^^^^^^^^^^^^^^^^^^^^^^^^^^^^^^^^^^^^^^^^^^^^^^^^^^^^^^^^^^^^^^^^^^^^^^^^^^^^^^^^^^^^
  File "/Users/yuyaarai/Documents/Humanics/Project/FormationFormatter/src/formationformatter/obj_chan/__init__.py", line 134, in <lambda>
    text_to_dict = lambda x: json.loads(x.replace('\'', '\"'))
                             ^^^^^^^^^^^^^^^^^^^^^^^^^^^^^^^^^
  File "/opt/homebrew/Cellar/python@3.12/3.12.8/Frameworks/Python.framework/Versions/3.12/lib/python3.12/json/__init__.py", line 346, in loads
    return _default_decoder.decode(s)
           ^^^^^^^^^^^^^^^^^^^^^^^^^^
  File "/opt/homebrew/Cellar/python@3.12/3.12.8/Frameworks/Python.framework/Versions/3.12/lib/python3.12/json/decoder.py", line 341, in decode
    raise JSONDecodeError("Extra data", s, end)
json.decoder.JSONDecodeError: Extra data: line 36 column 1 (char 572)
***2025-02-22 16:03:26.687236+00:00***: Retrying... (Attempt 6/10)***2025-02-22 16:03:30.337077+00:00***: obj-chan preprocess result:

{
  "labware": [
    {
      "name": "1.5 ml tube",
      "quantity": 1,
      "unit": "tube",
      "init_content": "",
      "labware": {
        "id": 1,
        "name": "Unknown"
      }
    },
    {
      "name": "96 well PCR plate",
      "quantity": 1,
      "unit": "plate",
      "init_content": "",
      "labware": {
        "id": 2,
        "name": "Unknown"
      }
    },
    {
      "name": "15 ml tube",
      "quantity": 1,
      "unit": "tube",
      "init_content": "",
      "labware": {
        "id": 3,
        "name": "Unknown"
      }
    }
  ]
}

Note: Since the labware mentioned in the given text is not already specified in the available labware list, the labware field has been left as "Unknown".***2025-02-22 16:03:30.338201+00:00***: obj-chan postprocess result:

{
  "labware": [
    {
      "name": "1.5 ml tube",
      "quantity": 1,
      "unit": "tube",
      "init_content": "",
      "labware": {
        "id": 1,
        "name": "Unknown"
      }
    },
    {
      "name": "96 well PCR plate",
      "quantity": 1,
      "unit": "plate",
      "init_content": "",
      "labware": {
        "id": 2,
        "name": "Unknown"
      }
    },
    {
      "name": "15 ml tube",
      "quantity": 1,
      "unit": "tube",
      "init_content": "",
      "labware": {
        "id": 3,
        "name": "Unknown"
      }
    }
  ]
}

Note: Since the labware mentioned in the given text is not already specified in the available labware list, the labware field has been left as "Unknown".***2025-02-22 16:03:30.338595+00:00***: Attempt 7 failed with error: Extra data: line 36 column 1 (char 572)***2025-02-22 16:03:30.339442+00:00***: Traceback: Traceback (most recent call last):
  File "/Users/yuyaarai/Documents/Humanics/Project/FormationFormatter/src/formationformatter/functions.py", line 45, in get_object_list
    object_list, obj_chan_errors = obj_chan(
                                   ^^^^^^^^^
  File "/Users/yuyaarai/Documents/Humanics/Project/FormationFormatter/src/formationformatter/obj_chan/__init__.py", line 265, in run
    res, errors = get_object_list(process_flow, constraints, messages, log_file_path=log_file_path)
                  ^^^^^^^^^^^^^^^^^^^^^^^^^^^^^^^^^^^^^^^^^^^^^^^^^^^^^^^^^^^^^^^^^^^^^^^^^^^^^^^^^
  File "/Users/yuyaarai/Documents/Humanics/Project/FormationFormatter/src/formationformatter/obj_chan/__init__.py", line 252, in get_object_list
    results = _extract_results_from_gpt_response(answer, log_file_path)
              ^^^^^^^^^^^^^^^^^^^^^^^^^^^^^^^^^^^^^^^^^^^^^^^^^^^^^^^^^
  File "/Users/yuyaarai/Documents/Humanics/Project/FormationFormatter/src/formationformatter/obj_chan/__init__.py", line 135, in _extract_results_from_gpt_response
    results = text_to_dict(result.replace('extracted_results:', '').replace('extracted_results_end:', '').strip())
              ^^^^^^^^^^^^^^^^^^^^^^^^^^^^^^^^^^^^^^^^^^^^^^^^^^^^^^^^^^^^^^^^^^^^^^^^^^^^^^^^^^^^^^^^^^^^^^^^^^^^
  File "/Users/yuyaarai/Documents/Humanics/Project/FormationFormatter/src/formationformatter/obj_chan/__init__.py", line 134, in <lambda>
    text_to_dict = lambda x: json.loads(x.replace('\'', '\"'))
                             ^^^^^^^^^^^^^^^^^^^^^^^^^^^^^^^^^
  File "/opt/homebrew/Cellar/python@3.12/3.12.8/Frameworks/Python.framework/Versions/3.12/lib/python3.12/json/__init__.py", line 346, in loads
    return _default_decoder.decode(s)
           ^^^^^^^^^^^^^^^^^^^^^^^^^^
  File "/opt/homebrew/Cellar/python@3.12/3.12.8/Frameworks/Python.framework/Versions/3.12/lib/python3.12/json/decoder.py", line 341, in decode
    raise JSONDecodeError("Extra data", s, end)
json.decoder.JSONDecodeError: Extra data: line 36 column 1 (char 572)
***2025-02-22 16:03:30.339842+00:00***: Retrying... (Attempt 7/10)***2025-02-22 16:03:30.734763+00:00***: Attempt 8 failed with error: This model's maximum context length is 16385 tokens. However, your messages resulted in 17995 tokens. Please reduce the length of the messages.***2025-02-22 16:03:30.736748+00:00***: Traceback: Traceback (most recent call last):
  File "/Users/yuyaarai/Documents/Humanics/Project/FormationFormatter/src/formationformatter/functions.py", line 45, in get_object_list
    object_list, obj_chan_errors = obj_chan(
                                   ^^^^^^^^^
  File "/Users/yuyaarai/Documents/Humanics/Project/FormationFormatter/src/formationformatter/obj_chan/__init__.py", line 265, in run
    res, errors = get_object_list(process_flow, constraints, messages, log_file_path=log_file_path)
                  ^^^^^^^^^^^^^^^^^^^^^^^^^^^^^^^^^^^^^^^^^^^^^^^^^^^^^^^^^^^^^^^^^^^^^^^^^^^^^^^^^
  File "/Users/yuyaarai/Documents/Humanics/Project/FormationFormatter/src/formationformatter/obj_chan/__init__.py", line 245, in get_object_list
    res = openai.ChatCompletion.create(
          ^^^^^^^^^^^^^^^^^^^^^^^^^^^^^
  File "/Users/yuyaarai/Documents/Humanics/Project/FormationFormatter/.venv/lib/python3.12/site-packages/openai/api_resources/chat_completion.py", line 25, in create
    return super().create(*args, **kwargs)
           ^^^^^^^^^^^^^^^^^^^^^^^^^^^^^^^
  File "/Users/yuyaarai/Documents/Humanics/Project/FormationFormatter/.venv/lib/python3.12/site-packages/openai/api_resources/abstract/engine_api_resource.py", line 153, in create
    response, _, api_key = requestor.request(
                           ^^^^^^^^^^^^^^^^^^
  File "/Users/yuyaarai/Documents/Humanics/Project/FormationFormatter/.venv/lib/python3.12/site-packages/openai/api_requestor.py", line 298, in request
    resp, got_stream = self._interpret_response(result, stream)
                       ^^^^^^^^^^^^^^^^^^^^^^^^^^^^^^^^^^^^^^^^
  File "/Users/yuyaarai/Documents/Humanics/Project/FormationFormatter/.venv/lib/python3.12/site-packages/openai/api_requestor.py", line 700, in _interpret_response
    self._interpret_response_line(
  File "/Users/yuyaarai/Documents/Humanics/Project/FormationFormatter/.venv/lib/python3.12/site-packages/openai/api_requestor.py", line 765, in _interpret_response_line
    raise self.handle_error_response(
openai.error.InvalidRequestError: This model's maximum context length is 16385 tokens. However, your messages resulted in 17995 tokens. Please reduce the length of the messages.
***2025-02-22 16:03:30.737321+00:00***: Retrying... (Attempt 8/10)***2025-02-22 16:03:31.276556+00:00***: Attempt 9 failed with error: This model's maximum context length is 16385 tokens. However, your messages resulted in 20028 tokens. Please reduce the length of the messages.***2025-02-22 16:03:31.279008+00:00***: Traceback: Traceback (most recent call last):
  File "/Users/yuyaarai/Documents/Humanics/Project/FormationFormatter/src/formationformatter/functions.py", line 45, in get_object_list
    object_list, obj_chan_errors = obj_chan(
                                   ^^^^^^^^^
  File "/Users/yuyaarai/Documents/Humanics/Project/FormationFormatter/src/formationformatter/obj_chan/__init__.py", line 265, in run
    res, errors = get_object_list(process_flow, constraints, messages, log_file_path=log_file_path)
                  ^^^^^^^^^^^^^^^^^^^^^^^^^^^^^^^^^^^^^^^^^^^^^^^^^^^^^^^^^^^^^^^^^^^^^^^^^^^^^^^^^
  File "/Users/yuyaarai/Documents/Humanics/Project/FormationFormatter/src/formationformatter/obj_chan/__init__.py", line 245, in get_object_list
    res = openai.ChatCompletion.create(
          ^^^^^^^^^^^^^^^^^^^^^^^^^^^^^
  File "/Users/yuyaarai/Documents/Humanics/Project/FormationFormatter/.venv/lib/python3.12/site-packages/openai/api_resources/chat_completion.py", line 25, in create
    return super().create(*args, **kwargs)
           ^^^^^^^^^^^^^^^^^^^^^^^^^^^^^^^
  File "/Users/yuyaarai/Documents/Humanics/Project/FormationFormatter/.venv/lib/python3.12/site-packages/openai/api_resources/abstract/engine_api_resource.py", line 153, in create
    response, _, api_key = requestor.request(
                           ^^^^^^^^^^^^^^^^^^
  File "/Users/yuyaarai/Documents/Humanics/Project/FormationFormatter/.venv/lib/python3.12/site-packages/openai/api_requestor.py", line 298, in request
    resp, got_stream = self._interpret_response(result, stream)
                       ^^^^^^^^^^^^^^^^^^^^^^^^^^^^^^^^^^^^^^^^
  File "/Users/yuyaarai/Documents/Humanics/Project/FormationFormatter/.venv/lib/python3.12/site-packages/openai/api_requestor.py", line 700, in _interpret_response
    self._interpret_response_line(
  File "/Users/yuyaarai/Documents/Humanics/Project/FormationFormatter/.venv/lib/python3.12/site-packages/openai/api_requestor.py", line 765, in _interpret_response_line
    raise self.handle_error_response(
openai.error.InvalidRequestError: This model's maximum context length is 16385 tokens. However, your messages resulted in 20028 tokens. Please reduce the length of the messages.
***2025-02-22 16:03:31.281216+00:00***: Retrying... (Attempt 9/10)***2025-02-22 16:03:31.801687+00:00***: Attempt 10 failed with error: This model's maximum context length is 16385 tokens. However, your messages resulted in 22061 tokens. Please reduce the length of the messages.***2025-02-22 16:03:31.805175+00:00***: Traceback: Traceback (most recent call last):
  File "/Users/yuyaarai/Documents/Humanics/Project/FormationFormatter/src/formationformatter/functions.py", line 45, in get_object_list
    object_list, obj_chan_errors = obj_chan(
                                   ^^^^^^^^^
  File "/Users/yuyaarai/Documents/Humanics/Project/FormationFormatter/src/formationformatter/obj_chan/__init__.py", line 265, in run
    res, errors = get_object_list(process_flow, constraints, messages, log_file_path=log_file_path)
                  ^^^^^^^^^^^^^^^^^^^^^^^^^^^^^^^^^^^^^^^^^^^^^^^^^^^^^^^^^^^^^^^^^^^^^^^^^^^^^^^^^
  File "/Users/yuyaarai/Documents/Humanics/Project/FormationFormatter/src/formationformatter/obj_chan/__init__.py", line 245, in get_object_list
    res = openai.ChatCompletion.create(
          ^^^^^^^^^^^^^^^^^^^^^^^^^^^^^
  File "/Users/yuyaarai/Documents/Humanics/Project/FormationFormatter/.venv/lib/python3.12/site-packages/openai/api_resources/chat_completion.py", line 25, in create
    return super().create(*args, **kwargs)
           ^^^^^^^^^^^^^^^^^^^^^^^^^^^^^^^
  File "/Users/yuyaarai/Documents/Humanics/Project/FormationFormatter/.venv/lib/python3.12/site-packages/openai/api_resources/abstract/engine_api_resource.py", line 153, in create
    response, _, api_key = requestor.request(
                           ^^^^^^^^^^^^^^^^^^
  File "/Users/yuyaarai/Documents/Humanics/Project/FormationFormatter/.venv/lib/python3.12/site-packages/openai/api_requestor.py", line 298, in request
    resp, got_stream = self._interpret_response(result, stream)
                       ^^^^^^^^^^^^^^^^^^^^^^^^^^^^^^^^^^^^^^^^
  File "/Users/yuyaarai/Documents/Humanics/Project/FormationFormatter/.venv/lib/python3.12/site-packages/openai/api_requestor.py", line 700, in _interpret_response
    self._interpret_response_line(
  File "/Users/yuyaarai/Documents/Humanics/Project/FormationFormatter/.venv/lib/python3.12/site-packages/openai/api_requestor.py", line 765, in _interpret_response_line
    raise self.handle_error_response(
openai.error.InvalidRequestError: This model's maximum context length is 16385 tokens. However, your messages resulted in 22061 tokens. Please reduce the length of the messages.
***2025-02-22 16:03:31.805837+00:00***: Retrying... (Attempt 10/10)***2025-02-22 16:03:31.806193+00:00***: ******************************************************************************2025-02-22 16:03:31.806433+00:00***: Failed to extract object list after 10 attempts.***2025-02-22 16:03:31.806660+00:00***: ******************************************************************************2025-02-22 16:03:31.806909+00:00***: object_list_num: 0